<?xml version="1.0" ?>
<!-- =================================================================================== -->
<!-- |    This document was autogenerated by xacro from /home/ws/pnk/ws/src/openarm_description/assets/robot/openarm_v1.0/urdf/openarm_v10.urdf.xacro | -->
<!-- |    EDITING THIS FILE BY HAND IS NOT RECOMMENDED                                 | -->
<!-- =================================================================================== -->
<!--
Copyright 2025 Enactic, Inc.
Licensed under the Apache License, Version 2.0 (the "License");
you may not use this file except in compliance with the License.
You may obtain a copy of the License at
    http://www.apache.org/licenses/LICENSE-2.0
Unless required by applicable law or agreed to in writing, software
distributed under the License is distributed on an "AS IS" BASIS,
WITHOUT WARRANTIES OR CONDITIONS OF ANY KIND, either express or implied.
See the License for the specific language governing permissions and
limitations under the License.
-->
<robot name="openarm">
  <link name="world"/>
  <joint name="openarm_body_world_joint" type="fixed">
    <parent link="world"/>
    <child link="openarm_body_link0"/>
    <origin rpy="0 0 0" xyz="0 0 0"/>
  </joint>
  <link name="openarm_body_link0">
    <visual name="openarm_body_link0_visual">
      <origin rpy="0.0 0.0 0.0" xyz="0.0 0.0 0.0"/>
      <geometry>
        <mesh filename="package://openarm_description/assets/robot/openarm_v1.0/mesh/body/visual/body_link0.dae" scale="0.001 0.001 0.001"/>
      </geometry>
    </visual>
    <collision name="openarm_body_link0_collision">
      <origin rpy="0.0 0.0 0.0" xyz="0.0 0.0 0.0"/>
      <geometry>
        <mesh filename="package://openarm_description/assets/robot/openarm_v1.0/mesh/body/collision/body_link0_symp.stl" scale="0.001 0.001 0.001"/>
        <!-- <mesh filename="package://openarm_description/meshes/arm/${arm_type}/collision/${name}.stl" scale="0.001 0.001 0.001" /> -->
      </geometry>
    </collision>
    <inertial>
      <origin rpy="0.0 0.0 0.0" xyz="0.0 0.0 0.0"/>
      <mass value="13.89"/>
      <inertia ixx="1.653" ixy="0.0" ixz="0.0" iyy="1.653" iyz="0.0" izz="0.051"/>
    </inertial>
  </link>
  <joint name="openarm_left_openarm_body_link0_joint" type="fixed">
    <parent link="openarm_body_link0"/>
    <child link="openarm_left_link0"/>
    <origin rpy="-1.5708 0 0" xyz="0.0 0.031 0.698"/>
  </joint>
  <link name="openarm_left_link0">
    <visual name="openarm_left_link0_visual">
      <origin rpy="0.0 0.0 0.0" xyz="0.0 0.0 0.0"/>
      <geometry>
        <mesh filename="package://openarm_description/assets/robot/openarm_v1.0/mesh/arm/visual/link0.dae" scale="0.001 -0.001 0.001"/>
      </geometry>
    </visual>
    <collision name="openarm_left_link0_collision">
      <origin rpy="0.0 0.0 0.0" xyz="0.0 0.0 0.0"/>
      <geometry>
        <mesh filename="package://openarm_description/assets/robot/openarm_v1.0/mesh/arm/collision/link0_symp.stl" scale="0.001 -0.001 0.001"/>
        <!-- <mesh filename="package://openarm_description/meshes/arm/${arm_type}/collision/${name}.stl" scale="0.001 0.001 0.001" /> -->
      </geometry>
    </collision>
    <inertial>
      <origin rpy="0.0 0.0 0.0" xyz="-0.0009483362816297526 -0.0001580207020448382 0.03076860287587199"/>
      <mass value="1.1432284943239561"/>
      <inertia ixx="0.001128" ixy="4e-06" ixz="-3.3e-05" iyy="0.000962" iyz="7e-06" izz="0.00147"/>
    </inertial>
  </link>
  <link name="openarm_left_link1">
    <visual name="openarm_left_link1_visual">
      <origin rpy="0.0 0.0 0.0" xyz="-0.0 0.0 -0.0625"/>
      <geometry>
        <mesh filename="package://openarm_description/assets/robot/openarm_v1.0/mesh/arm/visual/link1.dae" scale="0.001 -0.001 0.001"/>
      </geometry>
    </visual>
    <collision name="openarm_left_link1_collision">
      <origin rpy="0.0 0.0 0.0" xyz="-0.0 0.0 -0.0625"/>
      <geometry>
        <mesh filename="package://openarm_description/assets/robot/openarm_v1.0/mesh/arm/collision/link1_symp.stl" scale="0.001 -0.001 0.001"/>
        <!-- <mesh filename="package://openarm_description/meshes/arm/${arm_type}/collision/${name}.stl" scale="0.001 0.001 0.001" /> -->
      </geometry>
    </collision>
    <inertial>
      <origin rpy="0.0 0.0 0.0" xyz="0.0011467657911800769 -3.319987657026362e-05 0.05395284380736254"/>
      <mass value="1.1416684646202298"/>
      <inertia ixx="0.001567" ixy="1e-06" ixz="-2.9e-05" iyy="0.001273" iyz="-1e-06" izz="0.001016"/>
    </inertial>
  </link>
  <joint name="openarm_left_joint1" type="revolute">
    <origin rpy="0 0 0" xyz="0.0 0.0 0.0625"/>
    <parent link="openarm_left_link0"/>
    <child link="openarm_left_link1"/>
    <axis xyz="0 0 1"/>
    <limit effort="40" lower="-3.490659" upper="1.3962629999999998" velocity="16.754666"/>
  </joint>
  <link name="openarm_left_link2">
    <visual name="openarm_left_link2_visual">
      <origin rpy="0.0 0.0 0.0" xyz="0.0301 0.0 -0.1225"/>
      <geometry>
        <mesh filename="package://openarm_description/assets/robot/openarm_v1.0/mesh/arm/visual/link2.dae" scale="0.001 -0.001 0.001"/>
      </geometry>
    </visual>
    <collision name="openarm_left_link2_collision">
      <origin rpy="0.0 0.0 0.0" xyz="0.0301 0.0 -0.1225"/>
      <geometry>
        <mesh filename="package://openarm_description/assets/robot/openarm_v1.0/mesh/arm/collision/link2_symp.stl" scale="0.001 -0.001 0.001"/>
        <!-- <mesh filename="package://openarm_description/meshes/arm/${arm_type}/collision/${name}.stl" scale="0.001 0.001 0.001" /> -->
      </geometry>
    </collision>
    <inertial>
      <origin rpy="0.0 0.0 0.0" xyz="0.00839629182351943 2.0145102027597523e-08 0.03256649300522363"/>
      <mass value="0.2775092746011571"/>
      <inertia ixx="0.000359" ixy="-1e-06" ixz="-0.000109" iyy="0.000376" iyz="-1e-06" izz="0.000232"/>
    </inertial>
  </link>
  <joint name="openarm_left_joint2" type="revolute">
    <origin rpy="-1.57079632679 0 0" xyz="-0.0301 0.0 0.06"/>
    <parent link="openarm_left_link1"/>
    <child link="openarm_left_link2"/>
    <axis xyz="-1 0 0"/>
    <limit effort="40" lower="-3.3161253267948965" upper="0.17453267320510335" velocity="16.754666"/>
  </joint>
  <link name="openarm_left_link3">
    <visual name="openarm_left_link3_visual">
      <origin rpy="0.0 0.0 0.0" xyz="-0.0 -0.0 -0.18875"/>
      <geometry>
        <mesh filename="package://openarm_description/assets/robot/openarm_v1.0/mesh/arm/visual/link3.dae" scale="0.001 0.001 0.001"/>
      </geometry>
    </visual>
    <collision name="openarm_left_link3_collision">
      <origin rpy="0.0 0.0 0.0" xyz="-0.0 -0.0 -0.18875"/>
      <geometry>
        <mesh filename="package://openarm_description/assets/robot/openarm_v1.0/mesh/arm/collision/link3_symp.stl" scale="0.001 0.001 0.001"/>
        <!-- <mesh filename="package://openarm_description/meshes/arm/${arm_type}/collision/${name}.stl" scale="0.001 0.001 0.001" /> -->
      </geometry>
    </collision>
    <inertial>
      <origin rpy="0.0 0.0 0.0" xyz="-0.002104752099628911 0.0005549085042607548 0.09047470545721961"/>
      <mass value="1.073863338202347"/>
      <inertia ixx="0.004372" ixy="1e-06" ixz="1.1e-05" iyy="0.004319" iyz="-3.6e-05" izz="0.000661"/>
    </inertial>
  </link>
  <joint name="openarm_left_joint3" type="revolute">
    <origin rpy="0 0 0" xyz="0.0301 0.0 0.06625"/>
    <parent link="openarm_left_link2"/>
    <child link="openarm_left_link3"/>
    <axis xyz="0 0 1"/>
    <limit effort="27" lower="-1.570796" upper="1.570796" velocity="5.445426"/>
  </joint>
  <link name="openarm_left_link4">
    <visual name="openarm_left_link4_visual">
      <origin rpy="0.0 0.0 0.0" xyz="0.0 -0.0315 -0.3425"/>
      <geometry>
        <mesh filename="package://openarm_description/assets/robot/openarm_v1.0/mesh/arm/visual/link4.dae" scale="0.001 0.001 0.001"/>
      </geometry>
    </visual>
    <collision name="openarm_left_link4_collision">
      <origin rpy="0.0 0.0 0.0" xyz="0.0 -0.0315 -0.3425"/>
      <geometry>
        <mesh filename="package://openarm_description/assets/robot/openarm_v1.0/mesh/arm/collision/link4_symp.stl" scale="0.001 0.001 0.001"/>
        <!-- <mesh filename="package://openarm_description/meshes/arm/${arm_type}/collision/${name}.stl" scale="0.001 0.001 0.001" /> -->
      </geometry>
    </collision>
    <inertial>
      <origin rpy="0.0 0.0 0.0" xyz="-0.0029006831074562967 -0.03030575826634669 0.06339637422196209"/>
      <mass value="0.6348534566833373"/>
      <inertia ixx="0.000623" ixy="-1e-06" ixz="-1.9e-05" iyy="0.000511" iyz="3.8e-05" izz="0.000334"/>
    </inertial>
  </link>
  <joint name="openarm_left_joint4" type="revolute">
    <origin rpy="0 0 0" xyz="-0.0 0.0315 0.15375"/>
    <parent link="openarm_left_link3"/>
    <child link="openarm_left_link4"/>
    <axis xyz="0 1 0"/>
    <limit effort="27" lower="-0.01" upper="2.443461" velocity="5.445426"/>
  </joint>
  <link name="openarm_left_link5">
    <visual name="openarm_left_link5_visual">
      <origin rpy="0.0 0.0 0.0" xyz="-0.0 -0.0 -0.438"/>
      <geometry>
        <mesh filename="package://openarm_description/assets/robot/openarm_v1.0/mesh/arm/visual/link5.dae" scale="0.001 -0.001 0.001"/>
      </geometry>
    </visual>
    <collision name="openarm_left_link5_collision">
      <origin rpy="0.0 0.0 0.0" xyz="-0.0 -0.0 -0.438"/>
      <geometry>
        <mesh filename="package://openarm_description/assets/robot/openarm_v1.0/mesh/arm/collision/link5_symp.stl" scale="0.001 -0.001 0.001"/>
        <!-- <mesh filename="package://openarm_description/meshes/arm/${arm_type}/collision/${name}.stl" scale="0.001 0.001 0.001" /> -->
      </geometry>
    </collision>
    <inertial>
      <origin rpy="0.0 0.0 0.0" xyz="-0.003049665024221911 -0.0008866902457326625 0.043079803024980934"/>
      <mass value="0.6156588026168502"/>
      <inertia ixx="0.000423" ixy="8e-06" ixz="6e-06" iyy="0.000445" iyz="6e-06" izz="0.000324"/>
    </inertial>
  </link>
  <joint name="openarm_left_joint5" type="revolute">
    <origin rpy="0 0 0" xyz="0.0 -0.0315 0.0955"/>
    <parent link="openarm_left_link4"/>
    <child link="openarm_left_link5"/>
    <axis xyz="0 0 1"/>
    <limit effort="7" lower="-1.570796" upper="1.570796" velocity="20.943946"/>
  </joint>
  <link name="openarm_left_link6">
    <visual name="openarm_left_link6_visual">
      <origin rpy="0.0 0.0 0.0" xyz="-0.0375 -0.0 -0.5585"/>
      <geometry>
        <mesh filename="package://openarm_description/assets/robot/openarm_v1.0/mesh/arm/visual/link6.dae" scale="0.001 -0.001 0.001"/>
      </geometry>
    </visual>
    <collision name="openarm_left_link6_collision">
      <origin rpy="0.0 0.0 0.0" xyz="-0.0375 -0.0 -0.5585"/>
      <geometry>
        <mesh filename="package://openarm_description/assets/robot/openarm_v1.0/mesh/arm/collision/link6_symp.stl" scale="0.001 -0.001 0.001"/>
        <!-- <mesh filename="package://openarm_description/meshes/arm/${arm_type}/collision/${name}.stl" scale="0.001 0.001 0.001" /> -->
      </geometry>
    </collision>
    <inertial>
      <origin rpy="0.0 0.0 0.0" xyz="-0.037136587005447405 -0.00033230528343419053 -9.498374522309838e-05"/>
      <mass value="0.475202773187987"/>
      <inertia ixx="0.000143" ixy="-1e-06" ixz="1e-06" iyy="0.000157" iyz="-1e-06" izz="0.000159"/>
    </inertial>
  </link>
  <joint name="openarm_left_joint6" type="revolute">
    <origin rpy="0 0 0" xyz="0.0375 0.0 0.1205"/>
    <parent link="openarm_left_link5"/>
    <child link="openarm_left_link6"/>
    <axis xyz="1 0 0"/>
    <limit effort="7" lower="-0.785398" upper="0.785398" velocity="20.943946"/>
  </joint>
  <link name="openarm_left_link7">
    <visual name="openarm_left_link7_visual">
      <origin rpy="0.0 0.0 0.0" xyz="0.0 -0.0 -0.5585"/>
      <geometry>
        <mesh filename="package://openarm_description/assets/robot/openarm_v1.0/mesh/arm/visual/link7.dae" scale="0.001 -0.001 0.001"/>
      </geometry>
    </visual>
    <collision name="openarm_left_link7_collision">
      <origin rpy="0.0 0.0 0.0" xyz="0.0 -0.0 -0.5585"/>
      <geometry>
        <mesh filename="package://openarm_description/assets/robot/openarm_v1.0/mesh/arm/collision/link7_symp.stl" scale="0.001 -0.001 0.001"/>
        <!-- <mesh filename="package://openarm_description/meshes/arm/${arm_type}/collision/${name}.stl" scale="0.001 0.001 0.001" /> -->
      </geometry>
    </collision>
    <inertial>
      <origin rpy="0.0 0.0 0.0" xyz="6.875510271106056e-05 -0.01266175250761268 0.06951945409987448"/>
      <mass value="0.4659771327380578"/>
      <inertia ixx="0.000639" ixy="-1e-06" ixz="1e-06" iyy="0.000497" iyz="-8.9e-05" izz="0.000342"/>
    </inertial>
  </link>
  <joint name="openarm_left_joint7" type="revolute">
    <origin rpy="0 0 0" xyz="-0.0375 0.0 0.0"/>
    <parent link="openarm_left_link6"/>
    <child link="openarm_left_link7"/>
    <axis xyz="0 -1 0"/>
    <limit effort="7" lower="-1.570796" upper="1.570796" velocity="20.943946"/>
  </joint>
  <link name="openarm_left_tcp"/>
  <joint name="openarm_left_tcp_joint" type="fixed">
    <parent link="openarm_left_link7"/>
    <child link="openarm_left_tcp"/>
    <origin rpy="0 0 0" xyz="0 0 0.1"/>
  </joint>
  <joint name="openarm_right_openarm_body_link0_joint" type="fixed">
    <parent link="openarm_body_link0"/>
    <child link="openarm_right_link0"/>
    <origin rpy="1.5708 0 0" xyz="0.0 -0.031 0.698"/>
  </joint>
  <link name="openarm_right_link0">
    <visual name="openarm_right_link0_visual">
      <origin rpy="0.0 0.0 0.0" xyz="0.0 0.0 0.0"/>
      <geometry>
        <mesh filename="package://openarm_description/assets/robot/openarm_v1.0/mesh/arm/visual/link0.dae" scale="0.001 0.001 0.001"/>
      </geometry>
    </visual>
    <collision name="openarm_right_link0_collision">
      <origin rpy="0.0 0.0 0.0" xyz="0.0 0.0 0.0"/>
      <geometry>
        <mesh filename="package://openarm_description/assets/robot/openarm_v1.0/mesh/arm/collision/link0_symp.stl" scale="0.001 0.001 0.001"/>
        <!-- <mesh filename="package://openarm_description/meshes/arm/${arm_type}/collision/${name}.stl" scale="0.001 0.001 0.001" /> -->
      </geometry>
    </collision>
    <inertial>
      <origin rpy="0.0 0.0 0.0" xyz="-0.0009483362816297526 0.0001580207020448382 0.03076860287587199"/>
      <mass value="1.1432284943239561"/>
      <inertia ixx="0.001128" ixy="-4e-06" ixz="-3.3e-05" iyy="0.000962" iyz="-7e-06" izz="0.00147"/>
    </inertial>
  </link>
  <link name="openarm_right_link1">
    <visual name="openarm_right_link1_visual">
      <origin rpy="0.0 0.0 0.0" xyz="-0.0 0.0 -0.0625"/>
      <geometry>
        <mesh filename="package://openarm_description/assets/robot/openarm_v1.0/mesh/arm/visual/link1.dae" scale="0.001 0.001 0.001"/>
      </geometry>
    </visual>
    <collision name="openarm_right_link1_collision">
      <origin rpy="0.0 0.0 0.0" xyz="-0.0 0.0 -0.0625"/>
      <geometry>
        <mesh filename="package://openarm_description/assets/robot/openarm_v1.0/mesh/arm/collision/link1_symp.stl" scale="0.001 0.001 0.001"/>
        <!-- <mesh filename="package://openarm_description/meshes/arm/${arm_type}/collision/${name}.stl" scale="0.001 0.001 0.001" /> -->
      </geometry>
    </collision>
    <inertial>
      <origin rpy="0.0 0.0 0.0" xyz="0.0011467657911800769 3.319987657026362e-05 0.05395284380736254"/>
      <mass value="1.1416684646202298"/>
      <inertia ixx="0.001567" ixy="-1e-06" ixz="-2.9e-05" iyy="0.001273" iyz="1e-06" izz="0.001016"/>
    </inertial>
  </link>
  <joint name="openarm_right_joint1" type="revolute">
    <origin rpy="0 0 0" xyz="0.0 0.0 0.0625"/>
    <parent link="openarm_right_link0"/>
    <child link="openarm_right_link1"/>
    <axis xyz="0 0 1"/>
    <limit effort="40" lower="-1.396263" upper="3.490659" velocity="16.754666"/>
  </joint>
  <link name="openarm_right_link2">
    <visual name="openarm_right_link2_visual">
      <origin rpy="0.0 0.0 0.0" xyz="0.0301 0.0 -0.1225"/>
      <geometry>
        <mesh filename="package://openarm_description/assets/robot/openarm_v1.0/mesh/arm/visual/link2.dae" scale="0.001 0.001 0.001"/>
      </geometry>
    </visual>
    <collision name="openarm_right_link2_collision">
      <origin rpy="0.0 0.0 0.0" xyz="0.0301 0.0 -0.1225"/>
      <geometry>
        <mesh filename="package://openarm_description/assets/robot/openarm_v1.0/mesh/arm/collision/link2_symp.stl" scale="0.001 0.001 0.001"/>
        <!-- <mesh filename="package://openarm_description/meshes/arm/${arm_type}/collision/${name}.stl" scale="0.001 0.001 0.001" /> -->
      </geometry>
    </collision>
    <inertial>
      <origin rpy="0.0 0.0 0.0" xyz="0.00839629182351943 -2.0145102027597523e-08 0.03256649300522363"/>
      <mass value="0.2775092746011571"/>
      <inertia ixx="0.000359" ixy="1e-06" ixz="-0.000109" iyy="0.000376" iyz="1e-06" izz="0.000232"/>
    </inertial>
  </link>
  <joint name="openarm_right_joint2" type="revolute">
    <origin rpy="1.57079632679 0 0" xyz="-0.0301 0.0 0.06"/>
    <parent link="openarm_right_link1"/>
    <child link="openarm_right_link2"/>
    <axis xyz="-1 0 0"/>
    <limit effort="40" lower="-0.17453267320510335" upper="3.3161253267948965" velocity="16.754666"/>
  </joint>
  <link name="openarm_right_link3">
    <visual name="openarm_right_link3_visual">
      <origin rpy="0.0 0.0 0.0" xyz="-0.0 -0.0 -0.18875"/>
      <geometry>
        <mesh filename="package://openarm_description/assets/robot/openarm_v1.0/mesh/arm/visual/link3.dae" scale="0.001 0.001 0.001"/>
      </geometry>
    </visual>
    <collision name="openarm_right_link3_collision">
      <origin rpy="0.0 0.0 0.0" xyz="-0.0 -0.0 -0.18875"/>
      <geometry>
        <mesh filename="package://openarm_description/assets/robot/openarm_v1.0/mesh/arm/collision/link3_symp.stl" scale="0.001 0.001 0.001"/>
        <!-- <mesh filename="package://openarm_description/meshes/arm/${arm_type}/collision/${name}.stl" scale="0.001 0.001 0.001" /> -->
      </geometry>
    </collision>
    <inertial>
      <origin rpy="0.0 0.0 0.0" xyz="-0.002104752099628911 0.0005549085042607548 0.09047470545721961"/>
      <mass value="1.073863338202347"/>
      <inertia ixx="0.004372" ixy="1e-06" ixz="1.1e-05" iyy="0.004319" iyz="-3.6e-05" izz="0.000661"/>
    </inertial>
  </link>
  <joint name="openarm_right_joint3" type="revolute">
    <origin rpy="0 0 0" xyz="0.0301 0.0 0.06625"/>
    <parent link="openarm_right_link2"/>
    <child link="openarm_right_link3"/>
    <axis xyz="0 0 1"/>
    <limit effort="27" lower="-1.570796" upper="1.570796" velocity="5.445426"/>
  </joint>
  <link name="openarm_right_link4">
    <visual name="openarm_right_link4_visual">
      <origin rpy="0.0 0.0 0.0" xyz="0.0 -0.0315 -0.3425"/>
      <geometry>
        <mesh filename="package://openarm_description/assets/robot/openarm_v1.0/mesh/arm/visual/link4.dae" scale="0.001 0.001 0.001"/>
      </geometry>
    </visual>
    <collision name="openarm_right_link4_collision">
      <origin rpy="0.0 0.0 0.0" xyz="0.0 -0.0315 -0.3425"/>
      <geometry>
        <mesh filename="package://openarm_description/assets/robot/openarm_v1.0/mesh/arm/collision/link4_symp.stl" scale="0.001 0.001 0.001"/>
        <!-- <mesh filename="package://openarm_description/meshes/arm/${arm_type}/collision/${name}.stl" scale="0.001 0.001 0.001" /> -->
      </geometry>
    </collision>
    <inertial>
      <origin rpy="0.0 0.0 0.0" xyz="-0.0029006831074562967 -0.03030575826634669 0.06339637422196209"/>
      <mass value="0.6348534566833373"/>
      <inertia ixx="0.000623" ixy="-1e-06" ixz="-1.9e-05" iyy="0.000511" iyz="3.8e-05" izz="0.000334"/>
    </inertial>
  </link>
  <joint name="openarm_right_joint4" type="revolute">
    <origin rpy="0 0 0" xyz="-0.0 0.0315 0.15375"/>
    <parent link="openarm_right_link3"/>
    <child link="openarm_right_link4"/>
    <axis xyz="0 1 0"/>
    <limit effort="27" lower="-0.01" upper="2.443461" velocity="5.445426"/>
  </joint>
  <link name="openarm_right_link5">
    <visual name="openarm_right_link5_visual">
      <origin rpy="0.0 0.0 0.0" xyz="-0.0 -0.0 -0.438"/>
      <geometry>
        <mesh filename="package://openarm_description/assets/robot/openarm_v1.0/mesh/arm/visual/link5.dae" scale="0.001 0.001 0.001"/>
      </geometry>
    </visual>
    <collision name="openarm_right_link5_collision">
      <origin rpy="0.0 0.0 0.0" xyz="-0.0 -0.0 -0.438"/>
      <geometry>
        <mesh filename="package://openarm_description/assets/robot/openarm_v1.0/mesh/arm/collision/link5_symp.stl" scale="0.001 0.001 0.001"/>
        <!-- <mesh filename="package://openarm_description/meshes/arm/${arm_type}/collision/${name}.stl" scale="0.001 0.001 0.001" /> -->
      </geometry>
    </collision>
    <inertial>
      <origin rpy="0.0 0.0 0.0" xyz="-0.003049665024221911 0.0008866902457326625 0.043079803024980934"/>
      <mass value="0.6156588026168502"/>
      <inertia ixx="0.000423" ixy="-8e-06" ixz="6e-06" iyy="0.000445" iyz="-6e-06" izz="0.000324"/>
    </inertial>
  </link>
  <joint name="openarm_right_joint5" type="revolute">
    <origin rpy="0 0 0" xyz="0.0 -0.0315 0.0955"/>
    <parent link="openarm_right_link4"/>
    <child link="openarm_right_link5"/>
    <axis xyz="0 0 1"/>
    <limit effort="7" lower="-1.570796" upper="1.570796" velocity="20.943946"/>
  </joint>
  <link name="openarm_right_link6">
    <visual name="openarm_right_link6_visual">
      <origin rpy="0.0 0.0 0.0" xyz="-0.0375 -0.0 -0.5585"/>
      <geometry>
        <mesh filename="package://openarm_description/assets/robot/openarm_v1.0/mesh/arm/visual/link6.dae" scale="0.001 0.001 0.001"/>
      </geometry>
    </visual>
    <collision name="openarm_right_link6_collision">
      <origin rpy="0.0 0.0 0.0" xyz="-0.0375 -0.0 -0.5585"/>
      <geometry>
        <mesh filename="package://openarm_description/assets/robot/openarm_v1.0/mesh/arm/collision/link6_symp.stl" scale="0.001 0.001 0.001"/>
        <!-- <mesh filename="package://openarm_description/meshes/arm/${arm_type}/collision/${name}.stl" scale="0.001 0.001 0.001" /> -->
      </geometry>
    </collision>
    <inertial>
      <origin rpy="0.0 0.0 0.0" xyz="-0.037136587005447405 0.00033230528343419053 -9.498374522309838e-05"/>
      <mass value="0.475202773187987"/>
      <inertia ixx="0.000143" ixy="1e-06" ixz="1e-06" iyy="0.000157" iyz="1e-06" izz="0.000159"/>
    </inertial>
  </link>
  <joint name="openarm_right_joint6" type="revolute">
    <origin rpy="0 0 0" xyz="0.0375 0.0 0.1205"/>
    <parent link="openarm_right_link5"/>
    <child link="openarm_right_link6"/>
    <axis xyz="1 0 0"/>
    <limit effort="7" lower="-0.785398" upper="0.785398" velocity="20.943946"/>
  </joint>
  <link name="openarm_right_link7">
    <visual name="openarm_right_link7_visual">
      <origin rpy="0.0 0.0 0.0" xyz="0.0 -0.0 -0.5585"/>
      <geometry>
        <mesh filename="package://openarm_description/assets/robot/openarm_v1.0/mesh/arm/visual/link7.dae" scale="0.001 0.001 0.001"/>
      </geometry>
    </visual>
    <collision name="openarm_right_link7_collision">
      <origin rpy="0.0 0.0 0.0" xyz="0.0 -0.0 -0.5585"/>
      <geometry>
        <mesh filename="package://openarm_description/assets/robot/openarm_v1.0/mesh/arm/collision/link7_symp.stl" scale="0.001 0.001 0.001"/>
        <!-- <mesh filename="package://openarm_description/meshes/arm/${arm_type}/collision/${name}.stl" scale="0.001 0.001 0.001" /> -->
      </geometry>
    </collision>
    <inertial>
      <origin rpy="0.0 0.0 0.0" xyz="6.875510271106056e-05 0.01266175250761268 0.06951945409987448"/>
      <mass value="0.4659771327380578"/>
      <inertia ixx="0.000639" ixy="1e-06" ixz="1e-06" iyy="0.000497" iyz="8.9e-05" izz="0.000342"/>
    </inertial>
  </link>
  <joint name="openarm_right_joint7" type="revolute">
    <origin rpy="0 0 0" xyz="-0.0375 0.0 0.0"/>
    <parent link="openarm_right_link6"/>
    <child link="openarm_right_link7"/>
    <axis xyz="0 1 0"/>
    <limit effort="7" lower="-1.570796" upper="1.570796" velocity="20.943946"/>
  </joint>
  <link name="openarm_right_tcp"/>
  <joint name="openarm_right_tcp_joint" type="fixed">
    <parent link="openarm_right_link7"/>
    <child link="openarm_right_tcp"/>
    <origin rpy="0 0 0" xyz="0 0 0.1"/>
  </joint>
  <link name="left_base_link">
    <inertial>
      <origin rpy="0 0 0" xyz="-0.00526250771717109 0.00339255905687133 0.0521379173026012"/>
      <mass value="0.238"/>
      <inertia ixx="2.10902217235295E-05" ixy="-3.91382468722039E-08" ixz="9.20954665152033E-08" iyy="1.44592446991944E-05" iyz="1.10000625250951E-06" izz="7.99782051792634E-06"/>
    </inertial>
    <visual>
      <origin rpy="0 0 0" xyz="0 0 0"/>
      <geometry>
        <mesh filename="package://revo2_description/meshes/revo2_left_hand/left_base_link.STL"/>
      </geometry>
      <material name="">
        <color rgba="1 1 1 1"/>
      </material>
    </visual>
    <visual>
      <origin rpy="0 0 0" xyz="0 0 0"/>
      <geometry>
        <mesh filename="package://revo2_description/meshes/revo2_left_hand/left_base_visual_link.STL"/>
      </geometry>
      <material name="">
        <color rgba="1 1 1 1"/>
      </material>
    </visual>
    <collision>
      <origin rpy="0 0 0" xyz="0 0 0"/>
      <geometry>
        <mesh filename="package://revo2_description/meshes/revo2_left_hand/left_base_link.STL"/>
      </geometry>
    </collision>
  </link>
  <link name="left_thumb_metacarpal_link">
    <inertial>
      <origin rpy="0 0 0" xyz="1.52303696287076E-05 -0.00707240283482268 -0.00420839832903629"/>
      <mass value="0.01"/>
      <inertia ixx="1.59238866130872E-07" ixy="4.69114607598503E-09" ixz="4.93233725002151E-10" iyy="1.60911967461756E-07" iyz="1.48144948560702E-08" izz="5.13544258620214E-08"/>
    </inertial>
    <visual>
      <origin rpy="0 0 0" xyz="0 0 0"/>
      <geometry>
        <mesh filename="package://revo2_description/meshes/revo2_left_hand/left_thumb_metacarpal_link.STL"/>
      </geometry>
      <material name="">
        <color rgba="1 1 1 1"/>
      </material>
    </visual>
    <collision>
      <origin rpy="0 0 0" xyz="0 0 0"/>
      <geometry>
        <mesh filename="package://revo2_description/meshes/revo2_left_hand/left_thumb_metacarpal_link.STL"/>
      </geometry>
    </collision>
  </link>
  <joint name="left_thumb_metacarpal_joint" type="revolute">
    <origin rpy="0 0 0.16787" xyz="0.0045 -0.019 0.027825"/>
    <parent link="left_base_link"/>
    <child link="left_thumb_metacarpal_link"/>
    <axis xyz="0 0 1"/>
    <limit effort="0.5" lower="0" upper="1.57" velocity="2.6175"/>
  </joint>
  <link name="left_thumb_proximal_link">
    <inertial>
      <origin rpy="0 0 0" xyz="-3.69149416382109E-07 -0.0277015790929176 -0.00202668257181579"/>
      <mass value="0.05"/>
      <inertia ixx="2.40450829263392E-06" ixy="1.70278763843824E-10" ixz="1.21632944893438E-11" iyy="5.12299191364743E-07" iyz="2.89023502749285E-08" izz="2.56255682995404E-06"/>
    </inertial>
    <visual>
      <origin rpy="0 0 0" xyz="0 0 0"/>
      <geometry>
        <mesh filename="package://revo2_description/meshes/revo2_left_hand/left_thumb_proximal_link.STL"/>
      </geometry>
      <material name="">
        <color rgba="1 1 1 1"/>
      </material>
    </visual>
    <visual>
      <origin rpy="0 0 0" xyz="0 0 0"/>
      <geometry>
        <mesh filename="package://revo2_description/meshes/revo2_left_hand/left_thumb_proximal_visual_link.STL"/>
      </geometry>
      <material name="">
        <color rgba="1 1 1 1"/>
      </material>
    </visual>
    <collision>
      <origin rpy="0 0 0" xyz="0 0 0"/>
      <geometry>
        <mesh filename="package://revo2_description/meshes/revo2_left_hand/left_thumb_proximal_link.STL"/>
      </geometry>
    </collision>
  </link>
  <joint name="left_thumb_proximal_joint" type="revolute">
    <!-- 原点补偿：绕旋转轴 +9deg -->
    <origin rpy="-0.33153 0.23736 -0.16787" xyz="0 -0.014227 0"/>
    <parent link="left_thumb_metacarpal_link"/>
    <child link="left_thumb_proximal_link"/>
    <axis xyz="-1 0 0"/>
    <limit effort="1.1" lower="0" upper="1.03" velocity="2.5303"/>
  </joint>
  <link name="left_thumb_distal_link">
    <inertial>
      <origin rpy="0 0 0" xyz="1.65618684180163E-07 -0.0117550891981016 1.1366609064185E-05"/>
      <mass value="0.01"/>
      <inertia ixx="1.6780928553031E-07" ixy="1.91856562375217E-11" ixz="2.69475202672276E-12" iyy="1.15357239984326E-07" iyz="-1.25182560702847E-08" izz="2.1956615213811E-07"/>
    </inertial>
    <visual>
      <origin rpy="0 0 0" xyz="0 0 0"/>
      <geometry>
        <mesh filename="package://revo2_description/meshes/revo2_left_hand/left_thumb_distal_link.STL"/>
      </geometry>
      <material name="">
        <color rgba="1 1 1 1"/>
      </material>
    </visual>
    <collision>
      <origin rpy="0 0 0" xyz="0 0 0"/>
      <geometry>
        <mesh filename="package://revo2_description/meshes/revo2_left_hand/left_thumb_distal_link.STL"/>
      </geometry>
    </collision>
  </link>
  <joint name="left_thumb_distal_joint" type="revolute">
    <!-- 原点补偿：绕旋转轴 +6deg -->
    <origin rpy="0.10472 0 0" xyz="0 -0.052 0"/>
    <parent link="left_thumb_proximal_link"/>
    <child link="left_thumb_distal_link"/>
    <axis xyz="-1 0 0"/>
    <limit effort="1.1" lower="0" upper="1.03" velocity="2.5303"/>
    <mimic joint="left_thumb_proximal_joint" multiplier="0.691851" offset="0.0395854"/>
  </joint>
  <link name="left_thumb_tip_link">
    </link>
  <joint name="left_thumb_tip_joint" type="fixed">
    <origin rpy="0.06675 0 0" xyz="0 -0.026529 -0.0017734"/>
    <parent link="left_thumb_distal_link"/>
    <child link="left_thumb_tip_link"/>
    <axis xyz="0 0 0"/>
  </joint>
  <link name="left_thumb_touch_link">
    <inertial>
      <origin rpy="0 0 0" xyz="1.3569875392111E-07 0.000717207158422314 -0.00790252458933401"/>
      <mass value="0.002"/>
      <inertia ixx="1.67809287404785E-07" ixy="1.93619566820214E-11" ixz="-6.84472317111877E-13" iyy="1.14222234138764E-07" iyz="6.09432087624352E-09" izz="2.20701159969439E-07"/>
    </inertial>
    <visual>
      <origin rpy="0 0 0" xyz="0 0 0"/>
      <geometry>
        <mesh filename="package://revo2_description/meshes/revo2_left_hand/left_thumb_touch_link.STL"/>
      </geometry>
      <material name="">
        <color rgba="1 1 1 1"/>
      </material>
    </visual>
    <collision>
      <origin rpy="0 0 0" xyz="0 0 0"/>
      <geometry>
        <mesh filename="package://revo2_description/meshes/revo2_left_hand/left_thumb_touch_link.STL"/>
      </geometry>
    </collision>
  </link>
  <joint name="left_thumb_touch_joint" type="fixed">
    <origin rpy="0.17488 0 0" xyz="0 -0.013836 0.0076686"/>
    <parent link="left_thumb_distal_link"/>
    <child link="left_thumb_touch_link"/>
    <axis xyz="0 0 0"/>
  </joint>
  <link name="left_index_proximal_link">
    <inertial>
      <origin rpy="0 0 0" xyz="-0.002235387426012 -3.80544615179342E-06 0.0176439423080373"/>
      <mass value="0.009"/>
      <inertia ixx="2.51863526940901E-07" ixy="-3.10934654014342E-11" ixz="-6.36901300651623E-09" iyy="2.36343210839019E-07" iyz="-1.71663811116803E-10" izz="9.30397543724724E-08"/>
    </inertial>
    <visual>
      <origin rpy="0 0 0" xyz="0 0 0"/>
      <geometry>
        <mesh filename="package://revo2_description/meshes/revo2_left_hand/left_index_proximal_link.STL"/>
      </geometry>
      <material name="">
        <color rgba="1 1 1 1"/>
      </material>
    </visual>
    <collision>
      <origin rpy="0 0 0" xyz="0 0 0"/>
      <geometry>
        <mesh filename="package://revo2_description/meshes/revo2_left_hand/left_index_proximal_link.STL"/>
      </geometry>
    </collision>
  </link>
  <joint name="left_index_proximal_joint" type="revolute">
    <origin rpy="0.11819 0.14743 0.17422" xyz="-0.0021349 -0.029578 0.080876"/>
    <parent link="left_base_link"/>
    <child link="left_index_proximal_link"/>
    <axis xyz="0 1 0"/>
    <limit effort="2" lower="0" upper="1.41" velocity="2.2685"/>
  </joint>
  <link name="left_index_distal_link">
    <inertial>
      <origin rpy="0 0 0" xyz="0.00330165933067644 6.31887000952791E-08 0.0142075801783598"/>
      <mass value="0.009"/>
      <inertia ixx="3.39958467120803E-07" ixy="-2.00727556234471E-14" ixz="-8.7500943582372E-08" iyy="3.62235423626446E-07" iyz="2.21291910181288E-12" izz="9.10339055645575E-08"/>
    </inertial>
    <visual>
      <origin rpy="0 0 0" xyz="0 0 0"/>
      <geometry>
        <mesh filename="package://revo2_description/meshes/revo2_left_hand/left_index_distal_link.STL"/>
      </geometry>
      <material name="">
        <color rgba="1 1 1 1"/>
      </material>
    </visual>
    <collision>
      <origin rpy="0 0 0" xyz="0 0 0"/>
      <geometry>
        <mesh filename="package://revo2_description/meshes/revo2_left_hand/left_index_distal_link.STL"/>
      </geometry>
    </collision>
  </link>
  <joint name="left_index_distal_joint" type="revolute">
    <origin rpy="0 0 0" xyz="0 0 0.032"/>
    <parent link="left_index_proximal_link"/>
    <child link="left_index_distal_link"/>
    <axis xyz="0 1 0"/>
    <limit effort="2" lower="0" upper="1.63" velocity="2.2685"/>
    <mimic joint="left_index_proximal_joint" multiplier="1.155" offset="0"/>
  </joint>
  <link name="left_index_tip_link">
    </link>
  <joint name="left_index_tip_joint" type="fixed">
    <origin rpy="0 0.48723 0" xyz="0.011097 0 0.035739"/>
    <parent link="left_index_distal_link"/>
    <child link="left_index_tip_link"/>
    <axis xyz="0 0 0"/>
  </joint>
  <link name="left_index_touch_link">
    <inertial>
      <origin rpy="0 0 0" xyz="-0.00299918181799204 7.01974568750874E-09 0.00252369841562855"/>
      <mass value="0.002"/>
      <inertia ixx="6.77729843516625E-09" ixy="1.88703692893536E-14" ixz="1.51511606529797E-09" iyy="5.41485427527447E-09" iyz="7.54610125535653E-13" izz="3.19157470008512E-09"/>
    </inertial>
    <visual>
      <origin rpy="0 0 0" xyz="0 0 0"/>
      <geometry>
        <mesh filename="package://revo2_description/meshes/revo2_left_hand/left_index_touch_link.STL"/>
      </geometry>
      <material name="">
        <color rgba="1 1 1 1"/>
      </material>
    </visual>
    <collision>
      <origin rpy="0 0 0" xyz="0 0 0"/>
      <geometry>
        <mesh filename="package://revo2_description/meshes/revo2_left_hand/left_index_touch_link.STL"/>
      </geometry>
    </collision>
  </link>
  <joint name="left_index_touch_joint" type="fixed">
    <origin rpy="0 0.4756 0" xyz="0.014497 0 0.023303"/>
    <parent link="left_index_distal_link"/>
    <child link="left_index_touch_link"/>
    <axis xyz="0 0 0"/>
  </joint>
  <link name="left_middle_proximal_link">
    <inertial>
      <origin rpy="0 0 0" xyz="-0.00222419445309931 -3.61990820813788E-06 0.0203049526045434"/>
      <mass value="0.009"/>
      <inertia ixx="3.66885320718611E-07" ixy="-3.6430334370348E-11" ixz="-9.77995332041373E-09" iyy="3.5252138716754E-07" iyz="-2.58098211906242E-10" izz="1.12242284171831E-07"/>
    </inertial>
    <visual>
      <origin rpy="0 0 0" xyz="0 0 0"/>
      <geometry>
        <mesh filename="package://revo2_description/meshes/revo2_left_hand/left_middle_proximal_link.STL"/>
      </geometry>
      <material name="">
        <color rgba="1 1 1 1"/>
      </material>
    </visual>
    <collision>
      <origin rpy="0 0 0" xyz="0 0 0"/>
      <geometry>
        <mesh filename="package://revo2_description/meshes/revo2_left_hand/left_middle_proximal_link.STL"/>
      </geometry>
    </collision>
  </link>
  <joint name="left_middle_proximal_joint" type="revolute">
    <origin rpy="0.039468 0.1483 0.057975" xyz="-0.0045935 -0.010061 0.084993"/>
    <parent link="left_base_link"/>
    <child link="left_middle_proximal_link"/>
    <axis xyz="0 1 0"/>
    <limit effort="2" lower="0" upper="1.41" velocity="2.2685"/>
  </joint>
  <link name="left_middle_distal_link">
    <inertial>
      <origin rpy="0 0 0" xyz="0.00189418007863382 -2.26465967662765E-08 0.0168711148865022"/>
      <mass value="0.009"/>
      <inertia ixx="5.40534108976802E-07" ixy="2.94130244214777E-12" ixz="-8.35162930404456E-08" iyy="5.49812279010797E-07" iyz="7.84699400870312E-13" izz="9.55606707448008E-08"/>
    </inertial>
    <visual>
      <origin rpy="0 0 0" xyz="0 0 0"/>
      <geometry>
        <mesh filename="package://revo2_description/meshes/revo2_left_hand/left_middle_distal_link.STL"/>
      </geometry>
      <material name="">
        <color rgba="1 1 1 1"/>
      </material>
    </visual>
    <collision>
      <origin rpy="0 0 0" xyz="0 0 0"/>
      <geometry>
        <mesh filename="package://revo2_description/meshes/revo2_left_hand/left_middle_distal_link.STL"/>
      </geometry>
    </collision>
  </link>
  <joint name="left_middle_distal_joint" type="revolute">
    <origin rpy="0 0.12654 0" xyz="0 0 0.037"/>
    <parent link="left_middle_proximal_link"/>
    <child link="left_middle_distal_link"/>
    <axis xyz="0 1 0"/>
    <limit effort="2" lower="0" upper="1.63" velocity="2.2685"/>
    <mimic joint="left_middle_proximal_joint" multiplier="1.155" offset="0"/>
  </joint>
  <link name="left_middle_tip_link">
    </link>
  <joint name="left_middle_tip_joint" type="fixed">
    <origin rpy="0 0.34907 0" xyz="0.0073534 0 0.041703"/>
    <parent link="left_middle_distal_link"/>
    <child link="left_middle_tip_link"/>
    <axis xyz="0 0 0"/>
  </joint>
  <link name="left_middle_touch_link">
    <inertial>
      <origin rpy="0 0 0" xyz="-0.00319288866167638 -2.94334979245373E-08 0.00297859877777221"/>
      <mass value="0.002"/>
      <inertia ixx="1.00486919311226E-08" ixy="-5.43894280644511E-14" ixz="2.25918051958301E-09" iyy="8.23231100847473E-09" iyz="1.97875022250685E-13" izz="4.41272539147384E-09"/>
    </inertial>
    <visual>
      <origin rpy="0 0 0" xyz="0 0 0"/>
      <geometry>
        <mesh filename="package://revo2_description/meshes/revo2_left_hand/left_middle_touch_link.STL"/>
      </geometry>
      <material name="">
        <color rgba="1 1 1 1"/>
      </material>
    </visual>
    <collision>
      <origin rpy="0 0 0" xyz="0 0 0"/>
      <geometry>
        <mesh filename="package://revo2_description/meshes/revo2_left_hand/left_middle_touch_link.STL"/>
      </geometry>
    </collision>
  </link>
  <joint name="left_middle_touch_joint" type="fixed">
    <origin rpy="0 0.34907 0" xyz="0.012493 0 0.028393"/>
    <parent link="left_middle_distal_link"/>
    <child link="left_middle_touch_link"/>
    <axis xyz="0 0 0"/>
  </joint>
  <link name="left_ring_proximal_link">
    <inertial>
      <origin rpy="0 0 0" xyz="-0.00234461360118865 -5.32058096490429E-06 0.0191785931520923"/>
      <mass value="0.009"/>
      <inertia ixx="3.14182210853629E-07" ixy="-3.44825864493725E-11" ixz="-7.78011903077364E-09" iyy="2.97623388067888E-07" iyz="-2.45023710126397E-10" izz="1.02120946203075E-07"/>
    </inertial>
    <visual>
      <origin rpy="0 0 0" xyz="0 0 0"/>
      <geometry>
        <mesh filename="package://revo2_description/meshes/revo2_left_hand/left_ring_proximal_link.STL"/>
      </geometry>
      <material name="">
        <color rgba="1 1 1 1"/>
      </material>
    </visual>
    <collision>
      <origin rpy="0 0 0" xyz="0 0 0"/>
      <geometry>
        <mesh filename="package://revo2_description/meshes/revo2_left_hand/left_ring_proximal_link.STL"/>
      </geometry>
    </collision>
  </link>
  <joint name="left_ring_proximal_joint" type="revolute">
    <origin rpy="-0.039462 0.14721 -0.057932" xyz="-0.0046877 0.010026 0.083982"/>
    <parent link="left_base_link"/>
    <child link="left_ring_proximal_link"/>
    <axis xyz="0 1 0"/>
    <limit effort="2" lower="0" upper="1.41" velocity="2.2685"/>
  </joint>
  <link name="left_ring_distal_link">
    <inertial>
      <origin rpy="0 0 0" xyz="0.00177053636256925 6.44490570182732E-08 0.0163889588075686"/>
      <mass value="0.009"/>
      <inertia ixx="4.97910632685663E-07" ixy="-7.13155362656436E-13" ixz="-7.8333106177264E-08" iyy="5.06076323023651E-07" iyz="-3.12724415128725E-12" izz="8.96496585961614E-08"/>
    </inertial>
    <visual>
      <origin rpy="0 0 0" xyz="0 0 0"/>
      <geometry>
        <mesh filename="package://revo2_description/meshes/revo2_left_hand/left_ring_distal_link.STL"/>
      </geometry>
      <material name="">
        <color rgba="1 1 1 1"/>
      </material>
    </visual>
    <collision>
      <origin rpy="0 0 0" xyz="0 0 0"/>
      <geometry>
        <mesh filename="package://revo2_description/meshes/revo2_left_hand/left_ring_distal_link.STL"/>
      </geometry>
    </collision>
  </link>
  <joint name="left_ring_distal_joint" type="revolute">
    <origin rpy="0 0.12654 0" xyz="0 0 0.035"/>
    <parent link="left_ring_proximal_link"/>
    <child link="left_ring_distal_link"/>
    <axis xyz="0 1 0"/>
    <limit effort="2" lower="0" upper="1.63" velocity="2.2685"/>
    <mimic joint="left_ring_proximal_joint" multiplier="1.155" offset="0"/>
  </joint>
  <link name="left_ring_tip_link">
    </link>
  <joint name="left_ring_tip_joint" type="fixed">
    <origin rpy="0 0.34907 0" xyz="0.0071824 0 0.040734"/>
    <parent link="left_ring_distal_link"/>
    <child link="left_ring_tip_link"/>
    <axis xyz="0 0 0"/>
  </joint>
  <link name="left_ring_touch_link">
    <inertial>
      <origin rpy="0 0 0" xyz="-0.00302345977584328 -4.05745081005771E-08 0.00304075994548066"/>
      <mass value="0.002"/>
      <inertia ixx="8.20180397723655E-09" ixy="-4.46948642471342E-14" ixz="1.83211397314813E-09" iyy="6.6365125312521E-09" iyz="5.98352266349244E-14" izz="3.6192579315874E-09"/>
    </inertial>
    <visual>
      <origin rpy="0 0 0" xyz="0 0 0"/>
      <geometry>
        <mesh filename="package://revo2_description/meshes/revo2_left_hand/left_ring_touch_link.STL"/>
      </geometry>
      <material name="">
        <color rgba="1 1 1 1"/>
      </material>
    </visual>
    <collision>
      <origin rpy="0 0 0" xyz="0 0 0"/>
      <geometry>
        <mesh filename="package://revo2_description/meshes/revo2_left_hand/left_ring_touch_link.STL"/>
      </geometry>
    </collision>
  </link>
  <joint name="left_ring_touch_joint" type="fixed">
    <origin rpy="0 0.34907 0" xyz="0.012028 0 0.027796"/>
    <parent link="left_ring_distal_link"/>
    <child link="left_ring_touch_link"/>
    <axis xyz="0 0 0"/>
  </joint>
  <link name="left_pinky_proximal_link">
    <inertial>
      <origin rpy="0 0 0" xyz="-0.00213266608574047 -7.02260316783054E-06 0.0160680350593264"/>
      <mass value="0.009"/>
      <inertia ixx="1.97554078210582E-07" ixy="-1.34133676966674E-11" ixz="-4.58601823842206E-09" iyy="1.82022483454667E-07" iyz="-1.01838144940486E-10" izz="8.21758160050774E-08"/>
    </inertial>
    <visual>
      <origin rpy="0 0 0" xyz="0 0 0"/>
      <geometry>
        <mesh filename="package://revo2_description/meshes/revo2_left_hand/left_pinky_proximal_link.STL"/>
      </geometry>
      <material name="">
        <color rgba="1 1 1 1"/>
      </material>
    </visual>
    <collision>
      <origin rpy="0 0 0" xyz="0 0 0"/>
      <geometry>
        <mesh filename="package://revo2_description/meshes/revo2_left_hand/left_pinky_proximal_link.STL"/>
      </geometry>
    </collision>
  </link>
  <joint name="left_pinky_proximal_joint" type="revolute">
    <origin rpy="-0.11815 0.14491 -0.17392" xyz="-0.0023733 0.029356 0.078694"/>
    <parent link="left_base_link"/>
    <child link="left_pinky_proximal_link"/>
    <axis xyz="0 1 0"/>
    <limit effort="2" lower="0" upper="1.41" velocity="2.2685"/>
  </joint>
  <link name="left_pinky_distal_link">
    <inertial>
      <origin rpy="0 0 0" xyz="0.00307951040509596 -1.22880919793678E-07 0.0130238921688021"/>
      <mass value="0.009"/>
      <inertia ixx="2.70011721564217E-07" ixy="-3.87297641763705E-13" ixz="-6.70652466728246E-08" iyy="2.85232998853131E-07" iyz="2.31120225284722E-12" izz="7.90738051832137E-08"/>
    </inertial>
    <visual>
      <origin rpy="0 0 0" xyz="0 0 0"/>
      <geometry>
        <mesh filename="package://revo2_description/meshes/revo2_left_hand/left_pinky_distal_link.STL"/>
      </geometry>
      <material name="">
        <color rgba="1 1 1 1"/>
      </material>
    </visual>
    <collision>
      <origin rpy="0 0 0" xyz="0 0 0"/>
      <geometry>
        <mesh filename="package://revo2_description/meshes/revo2_left_hand/left_pinky_distal_link.STL"/>
      </geometry>
    </collision>
  </link>
  <joint name="left_pinky_distal_joint" type="revolute">
    <origin rpy="0 0 0" xyz="0 0 0.029"/>
    <parent link="left_pinky_proximal_link"/>
    <child link="left_pinky_distal_link"/>
    <axis xyz="0 1 0"/>
    <limit effort="2" lower="0" upper="1.63" velocity="2.2685"/>
    <mimic joint="left_pinky_proximal_joint" multiplier="1.155" offset="0"/>
  </joint>
  <link name="left_pinky_tip_link">
    </link>
  <joint name="left_pinky_tip_joint" type="fixed">
    <origin rpy="0 0.4756 0" xyz="0.010221 0 0.032918"/>
    <parent link="left_pinky_distal_link"/>
    <child link="left_pinky_tip_link"/>
    <axis xyz="0 0 0"/>
  </joint>
  <link name="left_pinky_touch_link">
    <inertial>
      <origin rpy="0 0 0" xyz="-0.00289141700902749 -2.11561558237372E-07 0.00165388079364141"/>
      <mass value="0.002"/>
      <inertia ixx="6.9191441933911E-09" ixy="1.05433982553728E-13" ixz="1.42746467369115E-09" iyy="5.34360711670272E-09" iyz="-7.73258724722553E-14" izz="3.28292125954561E-09"/>
    </inertial>
    <visual>
      <origin rpy="0 0 0" xyz="0 0 0"/>
      <geometry>
        <mesh filename="package://revo2_description/meshes/revo2_left_hand/left_pinky_touch_link.STL"/>
      </geometry>
      <material name="">
        <color rgba="1 1 1 1"/>
      </material>
    </visual>
    <collision>
      <origin rpy="0 0 0" xyz="0 0 0"/>
      <geometry>
        <mesh filename="package://revo2_description/meshes/revo2_left_hand/left_pinky_touch_link.STL"/>
      </geometry>
    </collision>
  </link>
  <joint name="left_pinky_touch_joint" type="fixed">
    <origin rpy="0 0.4756 0" xyz="0.01401 0 0.021124"/>
    <parent link="left_pinky_distal_link"/>
    <child link="left_pinky_touch_link"/>
    <axis xyz="0 0 0"/>
  </joint>
  <link name="right_base_link">
    <inertial>
      <origin rpy="0 0 0" xyz="-0.0052437813922142 -0.00340380255263376 0.0521266765719498"/>
      <mass value="0.238"/>
      <inertia ixx="2.10911666669912E-05" ixy="3.86322047662032E-08" ixz="9.36399145709391E-08" iyy="1.44621914759073E-05" iyz="-1.09576502000447E-06" izz="7.99811499549963E-06"/>
    </inertial>
    <visual>
      <origin rpy="0 0 0" xyz="0 0 0"/>
      <geometry>
        <mesh filename="package://revo2_description/meshes/revo2_right_hand/right_base_link.STL"/>
      </geometry>
      <material name="">
        <color rgba="1 1 1 1"/>
      </material>
    </visual>
    <visual>
      <origin rpy="0 0 0" xyz="0 0 0"/>
      <geometry>
        <mesh filename="package://revo2_description/meshes/revo2_right_hand/right_base_visual_link.STL"/>
      </geometry>
      <material name="">
        <color rgba="1 1 1 1"/>
      </material>
    </visual>
    <collision>
      <origin rpy="0 0 0" xyz="0 0 0"/>
      <geometry>
        <mesh filename="package://revo2_description/meshes/revo2_right_hand/right_base_link.STL"/>
      </geometry>
    </collision>
  </link>
  <link name="right_thumb_metacarpal_link">
    <inertial>
      <origin rpy="0 0 0" xyz="1.51105893291953E-05 0.00707242532016975 -0.00420847293427094"/>
      <mass value="0.01"/>
      <inertia ixx="1.59239837111329E-07" ixy="-4.69100836631313E-09" ixz="4.92933775261579E-10" iyy="1.60913456568321E-07" iyz="-1.48146725871811E-08" izz="5.13550255314669E-08"/>
    </inertial>
    <visual>
      <origin rpy="0 0 0" xyz="0 0 0"/>
      <geometry>
        <mesh filename="package://revo2_description/meshes/revo2_right_hand/right_thumb_metacarpal_link.STL"/>
      </geometry>
      <material name="">
        <color rgba="1 1 1 1"/>
      </material>
    </visual>
    <collision>
      <origin rpy="0 0 0" xyz="0 0 0"/>
      <geometry>
        <mesh filename="package://revo2_description/meshes/revo2_right_hand/right_thumb_metacarpal_link.STL"/>
      </geometry>
    </collision>
  </link>
  <joint name="right_thumb_metacarpal_joint" type="revolute">
    <origin rpy="0 0 -0.16787" xyz="0.005619 0.019867 0.027825"/>
    <parent link="right_base_link"/>
    <child link="right_thumb_metacarpal_link"/>
    <axis xyz="0 0 -1"/>
    <limit effort="0.5" lower="0" upper="1.57" velocity="2.6175"/>
  </joint>
  <link name="right_thumb_proximal_link">
    <inertial>
      <origin rpy="0 0 0" xyz="-4.69719500198473E-07 0.0277015013193164 -0.00202656319478134"/>
      <mass value="0.05"/>
      <inertia ixx="2.40451952538979E-06" ixy="-1.31092767621418E-10" ixz="8.32477243895752E-12" iyy="5.12323837647516E-07" iyz="-2.89154745634785E-08" izz="2.56254219597565E-06"/>
    </inertial>
    <visual>
      <origin rpy="0 0 0" xyz="0 0 0"/>
      <geometry>
        <mesh filename="package://revo2_description/meshes/revo2_right_hand/right_thumb_proximal_visual_link.STL"/>
      </geometry>
      <material name="">
        <color rgba="1 1 1 1"/>
      </material>
    </visual>
    <collision>
      <origin rpy="0 0 0" xyz="0 0 0"/>
      <geometry>
        <mesh filename="package://revo2_description/meshes/revo2_right_hand/right_thumb_proximal_link.STL"/>
      </geometry>
    </collision>
  </link>
  <joint name="right_thumb_proximal_joint" type="revolute">
    <!-- 原点补偿：绕旋转轴 +9deg -->
    <origin rpy="0.33153 0.23736 0.16787" xyz="0 0.014227 0"/>
    <parent link="right_thumb_metacarpal_link"/>
    <child link="right_thumb_proximal_link"/>
    <axis xyz="1 0 0"/>
    <limit effort="1.1" lower="0" upper="1.03" velocity="2.5303"/>
  </joint>
  <link name="right_thumb_distal_link">
    <inertial>
      <origin rpy="0 0 0" xyz="-5.88258312894663E-09 0.0117544716247141 1.13324397438934E-05"/>
      <mass value="0.01"/>
      <inertia ixx="1.67793545309794E-07" ixy="7.1592784782531E-12" ixz="-6.80095370887263E-12" iyy="1.15362128819332E-07" iyz="1.2517499089377E-08" izz="2.19553178338424E-07"/>
    </inertial>
    <visual>
      <origin rpy="0 0 0" xyz="0 0 0"/>
      <geometry>
        <mesh filename="package://revo2_description/meshes/revo2_right_hand/right_thumb_distal_link.STL"/>
      </geometry>
      <material name="">
        <color rgba="1 1 1 1"/>
      </material>
    </visual>
    <collision>
      <origin rpy="0 0 0" xyz="0 0 0"/>
      <geometry>
        <mesh filename="package://revo2_description/meshes/revo2_right_hand/right_thumb_distal_link.STL"/>
      </geometry>
    </collision>
  </link>
  <joint name="right_thumb_distal_joint" type="revolute">
    <!-- 原点补偿：绕旋转轴 +6deg -->
    <origin rpy="-0.10472 0 0" xyz="0 0.052 0"/>
    <parent link="right_thumb_proximal_link"/>
    <child link="right_thumb_distal_link"/>
    <axis xyz="1 0 0"/>
    <limit effort="1.1" lower="0" upper="1.03" velocity="2.5303"/>
    <mimic joint="right_thumb_proximal_joint" multiplier="0.691851" offset="0.0395854"/>
  </joint>
  <link name="right_thumb_tip_link"/>
  <joint name="right_thumb_tip_joint" type="fixed">
    <origin rpy="-0.0667504507189062 0 0" xyz="0 0.0265287811635831 -0.00177344281307929"/>
    <parent link="right_thumb_distal_link"/>
    <child link="right_thumb_tip_link"/>
    <axis xyz="0 0 0"/>
  </joint>
  <link name="right_thumb_touch_link">
    <inertial>
      <origin rpy="0 0 0" xyz="-1.1806027010175E-08 -0.00152252748962305 -0.00778417824955365"/>
      <mass value="0.002"/>
      <inertia ixx="1.67793545299225E-07" ixy="7.5594784738105E-12" ixz="-6.38541374289843E-12" iyy="1.14159537766499E-07" iyz="5.47195888787862E-09" izz="2.20755769355424E-07"/>
    </inertial>
    <visual>
      <origin rpy="0 0 0" xyz="0 0 0"/>
      <geometry>
        <mesh filename="package://revo2_description/meshes/revo2_right_hand/right_thumb_touch_link.STL"/>
      </geometry>
      <material name="">
        <color rgba="1 1 1 1"/>
      </material>
    </visual>
    <collision>
      <origin rpy="0 0 0" xyz="0 0 0"/>
      <geometry>
        <mesh filename="package://revo2_description/meshes/revo2_right_hand/right_thumb_touch_link.STL"/>
      </geometry>
    </collision>
  </link>
  <joint name="right_thumb_touch_joint" type="fixed">
    <origin rpy="-0.0667504507189062 0 0" xyz="0 0.0137927522748974 0.00767659940411662"/>
    <parent link="right_thumb_distal_link"/>
    <child link="right_thumb_touch_link"/>
    <axis xyz="0 0 0"/>
  </joint>
  <link name="right_index_proximal_link">
    <inertial>
      <origin rpy="0 0 0" xyz="-0.00223495193199565 3.15874577787312E-06 0.0176402020341366"/>
      <mass value="0.009"/>
      <inertia ixx="2.51945688372283E-07" ixy="1.19772964297278E-11" ixz="-6.37275644668917E-09" iyy="2.36435336139899E-07" iyz="1.65019165740599E-10" izz="9.30351046594029E-08"/>
    </inertial>
    <visual>
      <origin rpy="0 0 0" xyz="0 0 0"/>
      <geometry>
        <mesh filename="package://revo2_description/meshes/revo2_right_hand/right_index_proximal_link.STL"/>
      </geometry>
      <material name="">
        <color rgba="1 1 1 1"/>
      </material>
    </visual>
    <collision>
      <origin rpy="0 0 0" xyz="0 0 0"/>
      <geometry>
        <mesh filename="package://revo2_description/meshes/revo2_right_hand/right_index_proximal_link.STL"/>
      </geometry>
    </collision>
  </link>
  <joint name="right_index_proximal_joint" type="revolute">
    <origin rpy="-0.11819 0.14743 -0.17422" xyz="-0.0021181 0.029568 0.080876"/>
    <parent link="right_base_link"/>
    <child link="right_index_proximal_link"/>
    <axis xyz="0 1 0"/>
    <limit effort="2" lower="0" upper="1.41" velocity="2.2685"/>
  </joint>
  <link name="right_index_distal_link">
    <inertial>
      <origin rpy="0 0 0" xyz="0.00330169965345207 1.80502678033545E-07 0.0142076903844267"/>
      <mass value="0.009"/>
      <inertia ixx="3.39968050760851E-07" ixy="-2.72439842925177E-12" ixz="-8.75041192697868E-08" iyy="3.62244794159632E-07" iyz="-3.69168934117452E-12" izz="9.1034511229316E-08"/>
    </inertial>
    <visual>
      <origin rpy="0 0 0" xyz="0 0 0"/>
      <geometry>
        <mesh filename="package://revo2_description/meshes/revo2_right_hand/right_index_distal_link.STL"/>
      </geometry>
      <material name="">
        <color rgba="1 1 1 1"/>
      </material>
    </visual>
    <collision>
      <origin rpy="0 0 0" xyz="0 0 0"/>
      <geometry>
        <mesh filename="package://revo2_description/meshes/revo2_right_hand/right_index_distal_link.STL"/>
      </geometry>
    </collision>
  </link>
  <joint name="right_index_distal_joint" type="revolute">
    <origin rpy="0 0 0" xyz="0 0 0.032"/>
    <parent link="right_index_proximal_link"/>
    <child link="right_index_distal_link"/>
    <axis xyz="0 1 0"/>
    <limit effort="2" lower="0" upper="1.63" velocity="2.2685"/>
    <mimic joint="right_index_proximal_joint" multiplier="1.155" offset="0"/>
  </joint>
  <link name="right_index_tip_link"/>
  <joint name="right_index_tip_joint" type="fixed">
    <origin rpy="0 0.4756 0" xyz="0.011097 0 0.035739"/>
    <parent link="right_index_distal_link"/>
    <child link="right_index_tip_link"/>
    <axis xyz="0 0 0"/>
  </joint>
  <link name="right_index_touch_link">
    <inertial>
      <origin rpy="0 0 0" xyz="-0.00299911641156304 0.00249742609184543 -0.000361457745670764"/>
      <mass value="0.002"/>
      <inertia ixx="6.77691690725075E-09" ixy="1.49925053858217E-09" ixz="-2.16894115716066E-10" iyy="3.23801290825914E-09" iyz="3.14646833837905E-10" izz="5.36791538949697E-09"/>
    </inertial>
    <visual>
      <origin rpy="0 0 0" xyz="0 0 0"/>
      <geometry>
        <mesh filename="package://revo2_description/meshes/revo2_right_hand/right_index_touch_link.STL"/>
      </geometry>
      <material name="">
        <color rgba="1 1 1 1"/>
      </material>
    </visual>
    <collision>
      <origin rpy="0 0 0" xyz="0 0 0"/>
      <geometry>
        <mesh filename="package://revo2_description/meshes/revo2_right_hand/right_index_touch_link.STL"/>
      </geometry>
    </collision>
  </link>
  <joint name="right_index_touch_joint" type="fixed">
    <origin rpy="1.7145 0.4756 0" xyz="0.014497 0 0.023303"/>
    <parent link="right_index_distal_link"/>
    <child link="right_index_touch_link"/>
    <axis xyz="0 0 0"/>
  </joint>
  <link name="right_middle_proximal_link">
    <inertial>
      <origin rpy="0 0 0" xyz="-0.00222511101223747 5.25632286623237E-06 0.0203007776295123"/>
      <mass value="0.009"/>
      <inertia ixx="3.6699623719538E-07" ixy="2.68340899395639E-11" ixz="-9.79836587937102E-09" iyy="3.52645347928613E-07" iyz="2.5786558273981E-10" izz="1.12233932527467E-07"/>
    </inertial>
    <visual>
      <origin rpy="0 0 0" xyz="0 0 0"/>
      <geometry>
        <mesh filename="package://revo2_description/meshes/revo2_right_hand/right_middle_proximal_link.STL"/>
      </geometry>
      <material name="">
        <color rgba="1 1 1 1"/>
      </material>
    </visual>
    <collision>
      <origin rpy="0 0 0" xyz="0 0 0"/>
      <geometry>
        <mesh filename="package://revo2_description/meshes/revo2_right_hand/right_middle_proximal_link.STL"/>
      </geometry>
    </collision>
  </link>
  <joint name="right_middle_proximal_joint" type="revolute">
    <origin rpy="-0.039468 0.1483 -0.057975" xyz="-0.0045767 0.010051 0.084993"/>
    <parent link="right_base_link"/>
    <child link="right_middle_proximal_link"/>
    <axis xyz="0 1 0"/>
    <limit effort="2" lower="0" upper="1.41" velocity="2.2685"/>
  </joint>
  <link name="right_middle_distal_link">
    <inertial>
      <origin rpy="0 0 0" xyz="0.00400815246049972 -2.93852058033672E-08 0.0164973984498919"/>
      <mass value="0.009"/>
      <inertia ixx="5.12550471641205E-07" ixy="2.4957446124327E-12" ixz="-1.36569370373267E-07" iyy="5.4982769389762E-07" iyz="1.1510593712868E-12" izz="1.23560211132881E-07"/>
    </inertial>
    <visual>
      <origin rpy="0 0 0" xyz="0 0 0"/>
      <geometry>
        <mesh filename="package://revo2_description/meshes/revo2_right_hand/right_middle_distal_link.STL"/>
      </geometry>
      <material name="">
        <color rgba="1 1 1 1"/>
      </material>
    </visual>
    <collision>
      <origin rpy="0 0 0" xyz="0 0 0"/>
      <geometry>
        <mesh filename="package://revo2_description/meshes/revo2_right_hand/right_middle_distal_link.STL"/>
      </geometry>
    </collision>
  </link>
  <joint name="right_middle_distal_joint" type="revolute">
    <origin rpy="0 0 0" xyz="0 0 0.037"/>
    <parent link="right_middle_proximal_link"/>
    <child link="right_middle_distal_link"/>
    <axis xyz="0 1 0"/>
    <limit effort="2" lower="0" upper="1.63" velocity="2.2685"/>
    <mimic joint="right_middle_proximal_joint" multiplier="1.155" offset="0"/>
  </joint>
  <link name="right_middle_tip_link"/>
  <joint name="right_middle_tip_joint" type="fixed">
    <origin rpy="0 0.4756 0" xyz="0.012558 0 0.040442"/>
    <parent link="right_middle_distal_link"/>
    <child link="right_middle_tip_link"/>
    <axis xyz="0 0 0"/>
  </joint>
  <link name="right_middle_touch_link">
    <inertial>
      <origin rpy="0 0 0" xyz="-0.00319289171453651 -1.92251098651841E-08 0.00297860354010647"/>
      <mass value="0.002"/>
      <inertia ixx="1.00486658585813E-08" ixy="-7.87051809312931E-14" ixz="2.25917784171234E-09" iyy="8.23228109049258E-09" iyz="1.50825328552765E-13" izz="4.41272192206512E-09"/>
    </inertial>
    <visual>
      <origin rpy="0 0 0" xyz="0 0 0"/>
      <geometry>
        <mesh filename="package://revo2_description/meshes/revo2_right_hand/right_middle_touch_link.STL"/>
      </geometry>
      <material name="">
        <color rgba="1 1 1 1"/>
      </material>
    </visual>
    <collision>
      <origin rpy="0 0 0" xyz="0 0 0"/>
      <geometry>
        <mesh filename="package://revo2_description/meshes/revo2_right_hand/right_middle_touch_link.STL"/>
      </geometry>
    </collision>
  </link>
  <joint name="right_middle_touch_joint" type="fixed">
    <origin rpy="0 0.475602221168456 0" xyz="0.015975871997898 0 0.0265894268903603"/>
    <parent link="right_middle_distal_link"/>
    <child link="right_middle_touch_link"/>
    <axis xyz="0 0 0"/>
  </joint>
  <link name="right_ring_proximal_link">
    <inertial>
      <origin rpy="0 0 0" xyz="-0.00234494526421452 5.87954755621161E-06 0.019177402549597"/>
      <mass value="0.009"/>
      <inertia ixx="3.14177684848335E-07" ixy="3.34382331089976E-11" ixz="-7.78981780892183E-09" iyy="2.97613170150896E-07" iyz="2.41251871804457E-10" izz="1.0211543233675E-07"/>
    </inertial>
    <visual>
      <origin rpy="0 0 0" xyz="0 0 0"/>
      <geometry>
        <mesh filename="package://revo2_description/meshes/revo2_right_hand/right_ring_proximal_link.STL"/>
      </geometry>
      <material name="">
        <color rgba="1 1 1 1"/>
      </material>
    </visual>
    <collision>
      <origin rpy="0 0 0" xyz="0 0 0"/>
      <geometry>
        <mesh filename="package://revo2_description/meshes/revo2_right_hand/right_ring_proximal_link.STL"/>
      </geometry>
    </collision>
  </link>
  <joint name="right_ring_proximal_joint" type="revolute">
    <origin rpy="0.039462 0.14721 0.057932" xyz="-0.0046709 -0.010037 0.083982"/>
    <parent link="right_base_link"/>
    <child link="right_ring_proximal_link"/>
    <axis xyz="0 1 0"/>
    <limit effort="2" lower="0" upper="1.41" velocity="2.2685"/>
  </joint>
  <link name="right_ring_distal_link">
    <inertial>
      <origin rpy="0 0 0" xyz="0.00382459959210406 7.8017874437751E-08 0.0160343764410312"/>
      <mass value="0.009"/>
      <inertia ixx="4.71792497420504E-07" ixy="-6.95225674723301E-13" ixz="-1.26948440940938E-07" iyy="5.06071998616974E-07" iyz="-2.19413968646526E-12" izz="1.15762768100302E-07"/>
    </inertial>
    <visual>
      <origin rpy="0 0 0" xyz="0 0 0"/>
      <geometry>
        <mesh filename="package://revo2_description/meshes/revo2_right_hand/right_ring_distal_link.STL"/>
      </geometry>
      <material name="">
        <color rgba="1 1 1 1"/>
      </material>
    </visual>
    <collision>
      <origin rpy="0 0 0" xyz="0 0 0"/>
      <geometry>
        <mesh filename="package://revo2_description/meshes/revo2_right_hand/right_ring_distal_link.STL"/>
      </geometry>
    </collision>
  </link>
  <joint name="right_ring_distal_joint" type="revolute">
    <origin rpy="0 0 0" xyz="0 0 0.035"/>
    <parent link="right_ring_proximal_link"/>
    <child link="right_ring_distal_link"/>
    <axis xyz="0 1 0"/>
    <limit effort="2" lower="0" upper="1.63" velocity="2.2685"/>
    <mimic joint="right_ring_proximal_joint" multiplier="1.155" offset="0"/>
  </joint>
  <link name="right_ring_tip_link"/>
  <joint name="right_ring_tip_joint" type="fixed">
    <origin rpy="0 0.4756 0" xyz="0.012266 0 0.039501"/>
    <parent link="right_ring_distal_link"/>
    <child link="right_ring_tip_link"/>
    <axis xyz="0 0 0"/>
  </joint>
  <link name="right_ring_touch_link">
    <inertial>
      <origin rpy="0 0 0" xyz="-0.00302345770059939 -4.42584829375703E-08 0.0030407600788087"/>
      <mass value="0.002"/>
      <inertia ixx="8.20180993934663E-09" ixy="-2.63295949836146E-14" ixz="1.83211342144402E-09" iyy="6.63652036961065E-09" iyz="1.12534283673606E-13" izz="3.61925974724395E-09"/>
    </inertial>
    <visual>
      <origin rpy="0 0 0" xyz="0 0 0"/>
      <geometry>
        <mesh filename="package://revo2_description/meshes/revo2_right_hand/right_ring_touch_link.STL"/>
      </geometry>
      <material name="">
        <color rgba="1 1 1 1"/>
      </material>
    </visual>
    <collision>
      <origin rpy="0 0 0" xyz="0 0 0"/>
      <geometry>
        <mesh filename="package://revo2_description/meshes/revo2_right_hand/right_ring_touch_link.STL"/>
      </geometry>
    </collision>
  </link>
  <joint name="right_ring_touch_joint" type="fixed">
    <origin rpy="0 0.475602221168648 0" xyz="0.0154392324697935 0 0.0260561041381566"/>
    <parent link="right_ring_distal_link"/>
    <child link="right_ring_touch_link"/>
    <axis xyz="0 0 0"/>
  </joint>
  <link name="right_pinky_proximal_link">
    <inertial>
      <origin rpy="0 0 0" xyz="-0.00213212021184178 7.75039446098032E-06 0.0160671583560383"/>
      <mass value="0.009"/>
      <inertia ixx="1.97563213550085E-07" ixy="2.23402433057963E-11" ixz="-4.58425663692079E-09" iyy="1.82023043083307E-07" iyz="1.08028441152494E-10" izz="8.21624712033168E-08"/>
    </inertial>
    <visual>
      <origin rpy="0 0 0" xyz="0 0 0"/>
      <geometry>
        <mesh filename="package://revo2_description/meshes/revo2_right_hand/right_pinky_proximal_link.STL"/>
      </geometry>
      <material name="">
        <color rgba="1 1 1 1"/>
      </material>
    </visual>
    <collision>
      <origin rpy="0 0 0" xyz="0 0 0"/>
      <geometry>
        <mesh filename="package://revo2_description/meshes/revo2_right_hand/right_pinky_proximal_link.STL"/>
      </geometry>
    </collision>
  </link>
  <joint name="right_pinky_proximal_joint" type="revolute">
    <origin rpy="0.11815 0.14491 0.17392" xyz="-0.0023566 -0.029366 0.078694"/>
    <parent link="right_base_link"/>
    <child link="right_pinky_proximal_link"/>
    <axis xyz="0 1 0"/>
    <limit effort="2" lower="0" upper="1.41" velocity="2.2685"/>
  </joint>
  <link name="right_pinky_distal_link">
    <inertial>
      <origin rpy="0 0 0" xyz="0.00307974197235919 -1.54572112227858E-07 0.0130246967256256"/>
      <mass value="0.009"/>
      <inertia ixx="2.70050429038431E-07" ixy="1.68029751000565E-12" ixz="-6.70780254430148E-08" iyy="2.85275081521347E-07" iyz="5.10635117768255E-12" izz="7.90798706854226E-08"/>
    </inertial>
    <visual>
      <origin rpy="0 0 0" xyz="0 0 0"/>
      <geometry>
        <mesh filename="package://revo2_description/meshes/revo2_right_hand/right_pinky_distal_link.STL"/>
      </geometry>
      <material name="">
        <color rgba="1 1 1 1"/>
      </material>
    </visual>
    <collision>
      <origin rpy="0 0 0" xyz="0 0 0"/>
      <geometry>
        <mesh filename="package://revo2_description/meshes/revo2_right_hand/right_pinky_distal_link.STL"/>
      </geometry>
    </collision>
  </link>
  <joint name="right_pinky_distal_joint" type="revolute">
    <origin rpy="0 0 0" xyz="0 0 0.029"/>
    <parent link="right_pinky_proximal_link"/>
    <child link="right_pinky_distal_link"/>
    <axis xyz="0 1 0"/>
    <limit effort="2" lower="0" upper="1.63" velocity="2.2685"/>
    <mimic joint="right_pinky_proximal_joint" multiplier="1.155" offset="0"/>
  </joint>
  <link name="right_pinky_tip_link"/>
  <joint name="right_pinky_tip_joint" type="fixed">
    <origin rpy="0 0.4756 0" xyz="0.010221 0 0.032918"/>
    <parent link="right_pinky_distal_link"/>
    <child link="right_pinky_tip_link"/>
    <axis xyz="0 0 0"/>
  </joint>
  <link name="right_pinky_touch_link">
    <inertial>
      <origin rpy="0 0 0" xyz="-0.00289142401155668 -2.00563398826403E-07 0.00165387959177493"/>
      <mass value="0.002"/>
      <inertia ixx="6.91911795672566E-09" ixy="1.21758056374209E-13" ixz="1.42748611971717E-09" iyy="5.34364749688619E-09" iyz="7.16346527443829E-14" izz="3.28289727389894E-09"/>
    </inertial>
    <visual>
      <origin rpy="0 0 0" xyz="0 0 0"/>
      <geometry>
        <mesh filename="package://revo2_description/meshes/revo2_right_hand/right_pinky_touch_link.STL"/>
      </geometry>
      <material name="">
        <color rgba="1 1 1 1"/>
      </material>
    </visual>
    <collision>
      <origin rpy="0 0 0" xyz="0 0 0"/>
      <geometry>
        <mesh filename="package://revo2_description/meshes/revo2_right_hand/right_pinky_touch_link.STL"/>
      </geometry>
    </collision>
  </link>
  <joint name="right_pinky_touch_joint" type="fixed">
    <origin rpy="0 0.4756 0" xyz="0.01401 0 0.021124"/>
    <parent link="right_pinky_distal_link"/>
    <child link="right_pinky_touch_link"/>
    <axis xyz="0 0 0"/>
  </joint>
  <joint name="openarm_to_left_hand" type="fixed">
    <origin rpy="0 0 1.5" xyz="0 0 -0.05"/>
    <parent link="openarm_left_tcp"/>
    <child link="left_base_link"/>
  </joint>
  <joint name="openarm_to_right_hand" type="fixed">
    <origin rpy="0 0 -1.5" xyz="0 0 -0.05"/>
    <parent link="openarm_right_tcp"/>
    <child link="right_base_link"/>
  </joint>
</robot>
